Workbook

Sheet Instructions
A1: How to use this workbook
A2: Work through the 'Test Cases' sheet top to bottom. For each row set the Result cell (dropdown: Pass / Fail / Partial / N/A / Not run), and record what you saw in 'Actual / notes', plus your initials and the date. There are 131 cases across all feature areas. This is an internal self-check, not a formal/Quality validation. Use the Diagnostics sheet (or docs/Nucleus_Enhancer_Diagnostics.md) to capture detail when something misbehaves.
A3: Result colour key
A4: Pass | B4: Works as expected
A5: Fail | B5: Does not meet the expected result
A6: Partial | B6: Mostly works; note the caveat
A7: N/A | B7: Not applicable in this environment
A8: Not run | B8: Not yet tested
A9: Environment (record actuals)
A10: Browser + version | B10: Chrome ____ / Edge ____ (zoom 100%)
A11: OS | B11: Windows ____
A12: Salesforce org / sandbox | B12: ____
A13: Account & role | B13: ____ (admin / member / no-team)
A14: Extension version | B14: 3.0.0
A15: Tester | B15: ____
A16: Date | B16: ____

Sheet Test Cases
A1: CYFOR Nucleus Enhancer — Validation Results (v3.0.0)
A2: ID | B2: Area | C2: Feature | D2: Priority | E2: Pre-conditions | F2: Steps | G2: Expected result | H2: Result | I2: Actual / notes | J2: Tester | K2: Date
A3: Install & load
A4: I&L-01 | B4: Install & load | C4: Extension loads | D4: High | E4: Unpacked build loaded | F4: Open chrome://extensions | G4: Card shows, no errors; 'service worker' active (not 'errored')
A5: I&L-02 | B5: Install & load | C5: Content scripts inject | D5: High | E5: On a Salesforce Lightning page | F5: Open a Forensic Case / Exhibit Process record | G5: Injected UI appears (📄 button in Notes, nav arrows where applicable); page console shows no [Cyfor] errors
A6: I&L-03 | B6: Install & load | C6: Self-heal on update | D6: Medium | E6: A Salesforce tab already open | F6: Reload the extension (chrome://extensions ↻) WITHOUT refreshing the tab | G6: Injected features keep working / re-attach without a manual page refresh
A7: I&L-04 | B7: Install & load | C7: Service-worker fetch notice | D7: Low | E7: Edge extensions page | F7: Inspect the extension card | G7: Any 'unknown error fetching the script' is benign for unpacked builds; the worker still responds to a test command (Diagnostics §3)
A8: Popup — connection
A9: P—C-01 | B9: Popup — connection | C9: Initial state | D9: High | E9: Extension installed | F9: Open the popup before connecting | G9: Header 'Nucleus Enhancer' + version; connection shows 'Checking…' then 'Not connected'
A10: P—C-02 | B10: Popup — connection | C10: Connect Salesforce | D10: High | E10: Valid SF login | F10: Click 'Connect Salesforce', complete OAuth | G10: Returns connected: avatar, name, email; badge flips to connected
A11: P—C-03 | B11: Popup — connection | C11: Sync now | D11: High | E11: Connected | F11: Click 'Sync Now' | G11: Status shows syncing then 'N official templates · Last synced just now'
A12: P—C-04 | B12: Popup — connection | C12: Disconnect | D12: Medium | E12: Connected | F12: Click 'Disconnect' | G12: Returns to 'Not connected'; Quick Insert official count drops
A13: P—C-05 | B13: Popup — connection | C13: Offline handling | D13: Medium | E13: Disconnected / no network | F13: Open popup | G13: No crash; clear not-connected state; Quick Insert still lists local templates only
A14: Quick Insert
A15: QI-01 | B15: Quick Insert | C15: Loaded count | D15: Medium | E15: Templates synced/uploaded | F15: Open popup Quick Insert | G15: Badge shows 'N loaded'; dropdown 'Select template…' lists templates A–Z
A16: QI-02 | B16: Quick Insert | C16: Insert into active tab | D16: High | E16: On a SF Notes/Forensic Strategy field; template selected | F16: Click 'Insert into Active Tab' | G16: Template inserted into the active editor; popup closes; status '"name" sent ✓'
A17: QI-03 | B17: Quick Insert | C17: Insert with no editor | D17: Medium | E17: Not on an editor field | F17: Click Insert | G17: Clear message e.g. 'Navigate to a Salesforce page first' / 'click inside the Notes…'
A18: QI-04 | B18: Quick Insert | C18: Pin / unpin | D18: Medium | E18: Template selected | F18: Click ☆ | G18: Toggles ☆/★; pinned templates appear first in every menu; persists after reopen
A19: QI-05 | B19: Quick Insert | C19: Preview | D19: Low | E19: Template selected | F19: Click 'Preview' | G19: Preview pane shows up to ~400 chars; closes with ✕
A20: QI-06 | B20: Quick Insert | C20: Edit local vs official | D20: Medium | E20: Select an Official template | F20: Click 'Edit' | G20: Editor opens read-only with note that official templates are managed in Salesforce; Save disabled
A21: Core toggles
A22: CT-01 | B22: Core toggles | C22: Right-Click Quick-Fill | D22: Medium | E22: Popup open | F22: Toggle off, test a date field; toggle on | G22: Off = native menu; On = quick-fill works; state persists
A23: CT-02 | B23: Core toggles | C23: Right-Click Template Menu | D23: Medium | E23: Popup open | F23: Toggle off/on, right-click in Notes | G23: Off = no template menu; On = menu appears; persists
A24: CT-03 | B24: Core toggles | C24: Nav Arrows | D24: Low | E24: On Exhibit Process | F24: Toggle off/on | G24: Arrows/shortcuts disabled/enabled accordingly
A25: CT-04 | B25: Core toggles | C25: Format List Notes | D25: Low | E25: List view with notes | F25: Toggle off/on | G25: Notes formatting applied only when on
A26: CT-05 | B26: Core toggles | C26: Smart Auto-Insert | D26: Low | E26: New record form | F26: Toggle on; open empty Notes on a mapped process | G26: Template auto-inserted (toast 'Auto-inserted …'); off = suggestion only
A27: Columns
A28: C-01 | B28: Columns | C28: Detect columns | D28: Low | E28: List view open | F28: Open popup Table Columns | G28: Current table's columns listed; 'Scanning…' resolves
A29: C-02 | B29: Columns | C29: Reorder + reset | D29: Medium | E29: Columns listed | F29: Drag to reorder; then 'Reset' | G29: Table follows the drag live; Reset returns BOTH the live table AND the popup list to Salesforce's natural order
A30: C-03 | B30: Columns | C30: Save / load / overwrite preset | D30: Low | E30: Reordered | F30: Save Preset (name it); reorder differently; Load the preset from the dropdown; re-save under the same name | G30: Load APPLIES instantly to the live table (not just a popup preview); re-saving an existing name asks to confirm overwrite
A31: Process mappings
A32: PM-01 | B32: Process mappings | C32: Map process→template | D32: Low | E32: Templates loaded; Sense Check type exists | F32: Expand Process → Template Mappings; map a type incl. 'Sense Check' | G32: Mapping saved; used by Smart Auto-Insert/suggestion
A33: Template upload
A34: TU-01 | B34: Template upload | C34: Upload local .txt | D34: Low | E34: Have .txt files | F34: Select Template Folder | G34: 'N user templates loaded · M official'; official always win name clashes
A35: TU-02 | B35: Template upload | C35: Clear all | D35: Low | E35: Local templates loaded | F35: Click 'Clear All Templates' | G35: Local templates removed; official remain
A36: Theme
A37: T-01 | B37: Theme | C37: Picker Auto/Light/Dark | D37: Medium | E37: Popup open | F37: Click each theme option | G37: Popup restyles immediately; selected button pressed-state
A38: T-02 | B38: Theme | C38: Live switch to manager | D38: High | E38: Manager open in another tab | F38: Change theme in popup | G38: Open manager re-themes live with NO refresh
A39: T-03 | B39: Theme | C39: Live switch to page UI | D39: Medium | E39: SF page open | F39: Change theme | G39: Injected UI (menus/toasts) follows the theme
A40: T-04 | B40: Theme | C40: Auto follows OS | D40: Low | E40: Theme = Auto | F40: Change OS light/dark | G40: Surfaces follow the OS without refresh
...

Sheet Summary
A1: Summary
A2: Overall (live counts from the Result column)
A3: Pass | B3: =of:=COUNTIF('Test Cases'!H3:H400,"Pass") -> #VALUE!
A4: Fail | B4: =of:=COUNTIF('Test Cases'!H3:H400,"Fail") -> #VALUE!
A5: Partial | B5: =of:=COUNTIF('Test Cases'!H3:H400,"Partial") -> #VALUE!
A6: N/A | B6: =of:=COUNTIF('Test Cases'!H3:H400,"N/A") -> #VALUE!
A7: Not run | B7: =of:=COUNTIF('Test Cases'!H3:H400,"Not run") -> #VALUE!
A8: Total cases | B8: =of:=COUNTA('Test Cases'!A3:A400)-COUNTIF('Test Cases'!D3:D400,"") -> #VALUE!
A9: Per-area (Pass / Fail)
A10: Install & load | B10: =of:=COUNTIFS('Test Cases'!B3:B400,"Install & load",'Test Cases'!H3:H400,"Pass") -> #VALUE!
A11: Popup — connection | B11: =of:=COUNTIFS('Test Cases'!B3:B400,"Popup — connection",'Test Cases'!H3:H400,"Pass") -> #VALUE!
A12: Quick Insert | B12: =of:=COUNTIFS('Test Cases'!B3:B400,"Quick Insert",'Test Cases'!H3:H400,"Pass") -> #VALUE!
A13: Core toggles | B13: =of:=COUNTIFS('Test Cases'!B3:B400,"Core toggles",'Test Cases'!H3:H400,"Pass") -> #VALUE!
A14: Columns | B14: =of:=COUNTIFS('Test Cases'!B3:B400,"Columns",'Test Cases'!H3:H400,"Pass") -> #VALUE!
A15: Process mappings | B15: =of:=COUNTIFS('Test Cases'!B3:B400,"Process mappings",'Test Cases'!H3:H400,"Pass") -> #VALUE!
A16: Template upload | B16: =of:=COUNTIFS('Test Cases'!B3:B400,"Template upload",'Test Cases'!H3:H400,"Pass") -> #VALUE!
A17: Theme | B17: =of:=COUNTIFS('Test Cases'!B3:B400,"Theme",'Test Cases'!H3:H400,"Pass") -> #VALUE!
A18: Banners | B18: =of:=COUNTIFS('Test Cases'!B3:B400,"Banners",'Test Cases'!H3:H400,"Pass") -> #VALUE!
A19: Right-click | B19: =of:=COUNTIFS('Test Cases'!B3:B400,"Right-click",'Test Cases'!H3:H400,"Pass") -> #VALUE!
A20: Templates | B20: =of:=COUNTIFS('Test Cases'!B3:B400,"Templates",'Test Cases'!H3:H400,"Pass") -> #VALUE!
A21: Rich-text insert | B21: =of:=COUNTIFS('Test Cases'!B3:B400,"Rich-text insert",'Test Cases'!H3:H400,"Pass") -> #VALUE!
A22: Notes format | B22: =of:=COUNTIFS('Test Cases'!B3:B400,"Notes format",'Test Cases'!H3:H400,"Pass") -> #VALUE!
A23: Navigation | B23: =of:=COUNTIFS('Test Cases'!B3:B400,"Navigation",'Test Cases'!H3:H400,"Pass") -> #VALUE!
A24: Case alias | B24: =of:=COUNTIFS('Test Cases'!B3:B400,"Case alias",'Test Cases'!H3:H400,"Pass") -> #VALUE!
A25: Photo download | B25: =of:=COUNTIFS('Test Cases'!B3:B400,"Photo download",'Test Cases'!H3:H400,"Pass") -> #VALUE!
A26: Case report | B26: =of:=COUNTIFS('Test Cases'!B3:B400,"Case report",'Test Cases'!H3:H400,"Pass") -> #VALUE!
A27: Manager | B27: =of:=COUNTIFS('Test Cases'!B3:B400,"Manager",'Test Cases'!H3:H400,"Pass") -> #VALUE!
A28: Manager edit | B28: =of:=COUNTIFS('Test Cases'!B3:B400,"Manager edit",'Test Cases'!H3:H400,"Pass") -> #VALUE!
A29: RTE editor | B29: =of:=COUNTIFS('Test Cases'!B3:B400,"RTE editor",'Test Cases'!H3:H400,"Pass") -> #VALUE!
A30: Teams | B30: =of:=COUNTIFS('Test Cases'!B3:B400,"Teams",'Test Cases'!H3:H400,"Pass") -> #VALUE!
A31: History | B31: =of:=COUNTIFS('Test Cases'!B3:B400,"History",'Test Cases'!H3:H400,"Pass") -> #VALUE!
A32: Usage | B32: =of:=COUNTIFS('Test Cases'!B3:B400,"Usage",'Test Cases'!H3:H400,"Pass") -> #VALUE!
A33: Read-only | B33: =of:=COUNTIFS('Test Cases'!B3:B400,"Read-only",'Test Cases'!H3:H400,"Pass") -> #VALUE!
A34: Dark mode | B34: =of:=COUNTIFS('Test Cases'!B3:B400,"Dark mode",'Test Cases'!H3:H400,"Pass") -> #VALUE!
A35: Background | B35: =of:=COUNTIFS('Test Cases'!B3:B400,"Background",'Test Cases'!H3:H400,"Pass") -> #VALUE!
A36: Diagnostics | B36: =of:=COUNTIFS('Test Cases'!B3:B400,"Diagnostics",'Test Cases'!H3:H400,"Pass") -> #VALUE!
A37: Security | B37: =of:=COUNTIFS('Test Cases'!B3:B400,"Security",'Test Cases'!H3:H400,"Pass") -> #VALUE!
A38: Acknowledgements | B38: =of:=COUNTIFS('Test Cases'!B3:B400,"Acknowledgements",'Test Cases'!H3:H400,"Pass") -> #VALUE!
A39: Suggestions | B39: =of:=COUNTIFS('Test Cases'!B3:B400,"Suggestions",'Test Cases'!H3:H400,"Pass") -> #VALUE!
A40: UX | B40: =of:=COUNTIFS('Test Cases'!B3:B400,"UX",'Test Cases'!H3:H400,"Pass") -> #VALUE!

Sheet Diagnostics
A1: Diagnostics quick reference
A2: Capture a diagnostic log (easy) | B2: Popup → Diagnostics → switch ON 'Capture diagnostic log'. Refresh the Salesforce tab, reproduce the issue / run the tests, then Popup → 'Download log' to save a .txt to send to support. (The spreadsheet is your Pass/Fail record; this log is just technical detail for diagnosing failures.)
A3: Manual toggle (advanced) | B3: Service-worker console: chrome.storage.local.set({ cyforDebug: true }); then refresh the Salesforce tab. Disable with false.
A4: Open the service-worker console | B4: chrome://extensions → CYFOR Nucleus Enhancer → 'Inspect views: service worker'.
A5: Content-script logs | B5: Appear in the PAGE console (F12 on the Salesforce tab). Filter with [Cyfor.
A6: Inspect stored state | B6: chrome.storage.local.get(null, console.log) · sfOAuthUser · sfRemoteTemplates / sfTemplatesSyncedAt · usageLogError
A7: Force a sync | B7: chrome.runtime.sendMessage({action:'sfTemplates.sync', forceRefresh:true}, console.log)
A8: Check multi-team / limits | B8: chrome.runtime.sendMessage({action:'sfTemplates.listAll'}, r=>console.log(r.fields)) → fields.teamsMulti, fields.contentMaxLength
A9: Insertion path | B9: [Cyfor:insert] method = paste (good) vs insertHTML/innerHTML (fallback) — if rich content is lost, capture this.
A10: Right-click native menu | B10: Set browser zoom to 100% (zoom shifts elementFromPoint).
A11: Full cheat-sheet | B11: docs/Nucleus_Enhancer_Diagnostics.md
