Workbook

Sheet Instructions
A1: How to use this workbook
A2: Work through the 'Test Cases' sheet top to bottom. For each row set the Result cell (dropdown: Pass / Fail / Partial / N/A / Not run), and record what you saw in 'Actual / notes', plus your initials and the date. There are 141 cases across all feature areas. This is an internal self-check, not a formal/Quality validation. Use the Diagnostics sheet (or docs/Nucleus_Enhancer_Diagnostics.md) to capture detail when something misbehaves.
A3: Result colour key
A4: Pass | B4: Works as expected
A5: Fail | B5: Does not meet the expected result
A6: Partial | B6: Mostly works; note the caveat
A7: N/A | B7: Not applicable in this environment
A8: Not run | B8: Not yet tested
A9: Environment (record actuals)
A10: Browser + version | B10: Edge
A11: OS | B11: Windows
A12: Account & role | B12: Adam Jones (admin), Adam Jones Dev (standard user)
A13: Extension version | B13: 1.0.0
A14: Tester | B14: Adam Jones
A15: Date | B15: 46200

Sheet Test Cases
A1: ID | B1: Area | C1: Feature | D1: Priority | E1: Pre-conditions | F1: Steps | G1: Expected result | H1: Result | I1: Actual / notes | J1: Tester | K1: Date
A2: Install & load
A3: I&L-01 | B3: Install & load | C3: Extension loads | D3: High | E3: Unpacked build loaded | F3: Open chrome://extensions | G3: Card shows, no errors; 'service worker' active (not 'errored') | H3: Pass | J3: Adam Jones | K3: 46200
A4: I&L-02 | B4: Install & load | C4: Content scripts inject | D4: High | E4: On a Salesforce Lightning page | F4: Open a Forensic Case / Exhibit Process record | G4: Injected UI appears (📄 button in Notes, nav arrows where applicable); page console shows no [Cyfor] errors | H4: Pass | J4: Adam Jones | K4: 46200
A5: I&L-03 | B5: Install & load | C5: Self-heal on update | D5: Medium | E5: A Salesforce tab already open | F5: Reload the extension (chrome://extensions ↻) WITHOUT refreshing the tab | G5: Injected features keep working / re-attach without a manual page refresh | H5: Pass | J5: Adam Jones | K5: 46200
A6: I&L-04 | B6: Install & load | C6: Service-worker fetch notice | D6: Low | E6: Edge extensions page | F6: Inspect the extension card | G6: Any 'unknown error fetching the script' is benign for unpacked builds; the worker still responds to a test command (Diagnostics §3) | H6: Partial | I6: Some commands work and some give errors | J6: Adam Jones | K6: 46200
A7: Popup — connection
A8: P—C-01 | B8: Popup — connection | C8: Initial state | D8: High | E8: Extension installed | F8: Open the popup before connecting | G8: Header 'Nucleus Enhancer' + version; connection shows 'Checking…' then 'Not connected' | H8: Pass | J8: Adam Jones | K8: 46200
A9: P—C-02 | B9: Popup — connection | C9: Connect Salesforce | D9: High | E9: Valid SF login | F9: Click 'Connect Salesforce', complete OAuth | G9: Returns connected: avatar, name, email; badge flips to connected | H9: Pass | J9: Adam Jones | K9: 46200
A10: P—C-03 | B10: Popup — connection | C10: Sync now | D10: High | E10: Connected | F10: Click 'Sync Now' | G10: Status shows syncing then 'N official templates · Last synced just now' | H10: Pass | J10: Adam Jones | K10: 46200
A11: P—C-04 | B11: Popup — connection | C11: Disconnect | D11: Medium | E11: Connected | F11: Click 'Disconnect' | G11: Returns to 'Not connected'; Quick Insert official count drops | H11: Pass | J11: Adam Jones | K11: 46200
A12: P—C-05 | B12: Popup — connection | C12: Offline handling | D12: Medium | E12: Disconnected / no network | F12: Open popup | G12: No crash; clear not-connected state; Quick Insert still lists local templates only | H12: Pass | J12: Adam Jones | K12: 46200
A13: Quick Insert
A14: QI-01 | B14: Quick Insert | C14: Loaded count | D14: Medium | E14: Templates synced/uploaded | F14: Open popup Quick Insert | G14: Badge shows 'N loaded'; dropdown 'Select template…' lists templates A–Z | H14: Partial | I14: A-Z but prioritises capitals before lowercase | J14: Adam Jones | K14: 46200
A15: QI-02 | B15: Quick Insert | C15: Insert into active tab | D15: High | E15: On a SF Notes/Forensic Strategy field; template selected | F15: Click 'Insert into Active Tab' | G15: Template inserted into the active editor; popup closes; status '"name" sent ✓' | H15: Pass | J15: Adam Jones | K15: 46200
A16: QI-03 | B16: Quick Insert | C16: Insert with no editor | D16: Medium | E16: Not on an editor field | F16: Click Insert | G16: Clear message e.g. 'Navigate to a Salesforce page first' / 'click inside the Notes…' | H16: Pass | J16: Adam Jones | K16: 46200
A17: QI-04 | B17: Quick Insert | C17: Pin / unpin | D17: Medium | E17: Template selected | F17: Click ☆ | G17: Toggles ☆/★; pinned templates appear first in every menu; persists after reopen | H17: Pass | J17: Adam Jones | K17: 46200
A18: QI-05 | B18: Quick Insert | C18: Preview | D18: Low | E18: Template selected | F18: Click 'Preview' | G18: Preview pane shows up to ~400 chars; closes with ✕ | H18: Partial | I18: Template content visible but show style information relating to fonts etc instead of just the text | J18: Adam Jones | K18: 46200
A19: QI-06 | B19: Quick Insert | C19: Edit local vs official | D19: Medium | E19: Select an Official template | F19: Click 'Edit' | G19: Editor opens read-only with note that official templates are managed in Salesforce; Save disabled | H19: Pass | I19: Allows editing the local templates and not official but need to fix the formatting of the notes from the previous test | J19: Adam Jones | K19: 46200
A20: Core toggles
A21: CT-01 | B21: Core toggles | C21: Right-Click Quick-Fill | D21: Medium | E21: Popup open | F21: Toggle off, test a date field; toggle on | G21: Off = native menu; On = quick-fill works; state persists | H21: Pass | J21: Adam Jones | K21: 46200
A22: CT-02 | B22: Core toggles | C22: Right-Click Template Menu | D22: Medium | E22: Popup open | F22: Toggle off/on, right-click in Notes | G22: Off = no template menu; On = menu appears; persists | H22: Pass | J22: Adam Jones | K22: 46200
A23: CT-03 | B23: Core toggles | C23: Nav Arrows | D23: Low | E23: On Exhibit Process | F23: Toggle off/on | G23: Arrows/shortcuts disabled/enabled accordingly | H23: Pass | J23: Adam Jones | K23: 46200
A24: CT-04 | B24: Core toggles | C24: Format List Notes | D24: Low | E24: List view with notes | F24: Toggle off/on | G24: Notes formatting applied only when on | H24: Partial | I24: When turning off format notes toggle in pop up menu I need to refresh for it to work | J24: Adam Jones | K24: 46200
A25: CT-05 | B25: Core toggles | C25: Smart Auto-Insert | D25: Low | E25: New record form | F25: Toggle on; open empty Notes on a mapped process | G25: Template auto-inserted (toast 'Auto-inserted …'); off = suggestion only | H25: Pass | J25: Adam Jones | K25: 46200
A26: Columns
A27: C-01 | B27: Columns | C27: Detect columns | D27: Low | E27: List view open | F27: Open popup Table Columns | G27: Current table's columns listed; 'Scanning…' resolves | H27: Pass | J27: Adam Jones | K27: 46200
A28: C-02 | B28: Columns | C28: Reorder + reset | D28: Medium | E28: Columns listed | F28: Drag to reorder; then 'Reset' | G28: Table follows the drag live; Reset returns BOTH the live table AND the popup list to Salesforce's natural order | H28: Pass | J28: Adam Jones | K28: 46200
A29: C-03 | B29: Columns | C29: Save / load / overwrite preset | D29: Low | E29: Reordered | F29: Save Preset (name it); reorder differently; Load the preset from the dropdown; re-save under the same name | G29: Load APPLIES instantly to the live table (not just a popup preview); re-saving an existing name asks to confirm overwrite | H29: Pass | J29: Adam Jones | K29: 46200
A30: Process mappings
A31: PM-01 | B31: Process mappings | C31: Map process→template | D31: Low | E31: Templates loaded; Sense Check type exists | F31: Expand Process → Template Mappings; map a type incl. 'Sense Check' | G31: Mapping saved; used by Smart Auto-Insert/suggestion | H31: Pass | J31: Adam Jones | K31: 46200
A32: Template upload
A33: TU-01 | B33: Template upload | C33: Upload local .txt | D33: Low | E33: Have .txt files | F33: Select Template Folder | G33: 'N user templates loaded · M official'; official always win name clashes | H33: Pass | J33: Adam Jones | K33: 46200
A34: TU-02 | B34: Template upload | C34: Clear all | D34: Low | E34: Local templates loaded | F34: Click 'Clear All Templates' | G34: Local templates removed; official remain | H34: Pass | J34: Adam Jones | K34: 46200
A35: Theme
A36: T-01 | B36: Theme | C36: Picker Auto/Light/Dark | D36: Medium | E36: Popup open | F36: Click each theme option | G36: Popup restyles immediately; selected button pressed-state | H36: Pass | J36: Adam Jones | K36: 46200
A37: T-02 | B37: Theme | C37: Live switch to manager | D37: High | E37: Manager open in another tab | F37: Change theme in popup | G37: Open manager re-themes live with NO refresh | H37: Pass | J37: Adam Jones | K37: 46200
A38: T-03 | B38: Theme | C38: Live switch to page UI | D38: Medium | E38: SF page open | F38: Change theme | G38: Injected UI (menus/toasts) follows the theme | H38: Pass | J38: Adam Jones | K38: 46200
A39: T-04 | B39: Theme | C39: Auto follows OS | D39: Low | E39: Theme = Auto | F39: Change OS light/dark | G39: Surfaces follow the OS without refresh | H39: Pass | J39: Adam Jones | K39: 46200
A40: Banners
...

Sheet Summary
A1: Overall Summary | B1: Count
A2: Pass | B2: =COUNTIF('Test Cases'!H:H, "Pass") -> 130
A3: Fail | B3: =COUNTIF('Test Cases'!H:H, "Fail") -> 4
A4: Partial | B4: =COUNTIF('Test Cases'!H:H, "Partial") -> 5
A5: N/A | B5: =COUNTIF('Test Cases'!H:H, "N/A") -> 2
A6: Not run | B6: =COUNTIF('Test Cases'!H:H, "Not run") -> 1
A7: Total cases | B7: =SUM(B2:B6) -> 142
A9: Per-area (Pass / Fail) | B9: Pass | C9: Fail | D9: Partial | E9: Not run / NA
A10: Install & load | B10: =COUNTIFS('Test Cases'!B:B, "Install & load", 'Test Cases'!H:H, "Pass") -> 3 | C10: =COUNTIFS('Test Cases'!B:B, "Install & load", 'Test Cases'!H:H, "Fail") -> 0 | D10: =COUNTIFS('Test Cases'!B:B, "Install & load", 'Test Cases'!H:H, "Partial") -> 1 | E10: =COUNTIFS('Test Cases'!B:B, "Install & load", 'Test Cases'!H:H, "<>Pass", 'Test Cases'!H:H, "<>Fail", 'Test Cases'!H:H, "<>Partial", 'Test Cases'!H:H, "<>") -> 0
A11: Popup — connection | B11: =COUNTIFS('Test Cases'!B:B, "Popup — connection", 'Test Cases'!H:H, "Pass") -> 5 | C11: =COUNTIFS('Test Cases'!B:B, "Popup — connection", 'Test Cases'!H:H, "Fail") -> 0 | D11: =COUNTIFS('Test Cases'!B:B, "Popup — connection", 'Test Cases'!H:H, "Partial") -> 0 | E11: =COUNTIFS('Test Cases'!B:B, "Popup — connection", 'Test Cases'!H:H, "<>Pass", 'Test Cases'!H:H, "<>Fail", 'Test Cases'!H:H, "<>Partial", 'Test Cases'!H:H, "<>") -> 0
A12: Quick Insert | B12: =COUNTIFS('Test Cases'!B:B, "Quick Insert", 'Test Cases'!H:H, "Pass") -> 4 | C12: =COUNTIFS('Test Cases'!B:B, "Quick Insert", 'Test Cases'!H:H, "Fail") -> 0 | D12: =COUNTIFS('Test Cases'!B:B, "Quick Insert", 'Test Cases'!H:H, "Partial") -> 2 | E12: =COUNTIFS('Test Cases'!B:B, "Quick Insert", 'Test Cases'!H:H, "<>Pass", 'Test Cases'!H:H, "<>Fail", 'Test Cases'!H:H, "<>Partial", 'Test Cases'!H:H, "<>") -> 0
A13: Core toggles | B13: =COUNTIFS('Test Cases'!B:B, "Core toggles", 'Test Cases'!H:H, "Pass") -> 4 | C13: =COUNTIFS('Test Cases'!B:B, "Core toggles", 'Test Cases'!H:H, "Fail") -> 0 | D13: =COUNTIFS('Test Cases'!B:B, "Core toggles", 'Test Cases'!H:H, "Partial") -> 1 | E13: =COUNTIFS('Test Cases'!B:B, "Core toggles", 'Test Cases'!H:H, "<>Pass", 'Test Cases'!H:H, "<>Fail", 'Test Cases'!H:H, "<>Partial", 'Test Cases'!H:H, "<>") -> 0
A14: Columns | B14: =COUNTIFS('Test Cases'!B:B, "Columns", 'Test Cases'!H:H, "Pass") -> 3 | C14: =COUNTIFS('Test Cases'!B:B, "Columns", 'Test Cases'!H:H, "Fail") -> 0 | D14: =COUNTIFS('Test Cases'!B:B, "Columns", 'Test Cases'!H:H, "Partial") -> 0 | E14: =COUNTIFS('Test Cases'!B:B, "Columns", 'Test Cases'!H:H, "<>Pass", 'Test Cases'!H:H, "<>Fail", 'Test Cases'!H:H, "<>Partial", 'Test Cases'!H:H, "<>") -> 0
A15: Process mappings | B15: =COUNTIFS('Test Cases'!B:B, "Process mappings", 'Test Cases'!H:H, "Pass") -> 1 | C15: =COUNTIFS('Test Cases'!B:B, "Process mappings", 'Test Cases'!H:H, "Fail") -> 0 | D15: =COUNTIFS('Test Cases'!B:B, "Process mappings", 'Test Cases'!H:H, "Partial") -> 0 | E15: =COUNTIFS('Test Cases'!B:B, "Process mappings", 'Test Cases'!H:H, "<>Pass", 'Test Cases'!H:H, "<>Fail", 'Test Cases'!H:H, "<>Partial", 'Test Cases'!H:H, "<>") -> 0
A16: Template upload | B16: =COUNTIFS('Test Cases'!B:B, "Template upload", 'Test Cases'!H:H, "Pass") -> 2 | C16: =COUNTIFS('Test Cases'!B:B, "Template upload", 'Test Cases'!H:H, "Fail") -> 0 | D16: =COUNTIFS('Test Cases'!B:B, "Template upload", 'Test Cases'!H:H, "Partial") -> 0 | E16: =COUNTIFS('Test Cases'!B:B, "Template upload", 'Test Cases'!H:H, "<>Pass", 'Test Cases'!H:H, "<>Fail", 'Test Cases'!H:H, "<>Partial", 'Test Cases'!H:H, "<>") -> 0
A17: Theme | B17: =COUNTIFS('Test Cases'!B:B, "Theme", 'Test Cases'!H:H, "Pass") -> 4 | C17: =COUNTIFS('Test Cases'!B:B, "Theme", 'Test Cases'!H:H, "Fail") -> 0 | D17: =COUNTIFS('Test Cases'!B:B, "Theme", 'Test Cases'!H:H, "Partial") -> 0 | E17: =COUNTIFS('Test Cases'!B:B, "Theme", 'Test Cases'!H:H, "<>Pass", 'Test Cases'!H:H, "<>Fail", 'Test Cases'!H:H, "<>Partial", 'Test Cases'!H:H, "<>") -> 0
A18: Banners | B18: =COUNTIFS('Test Cases'!B:B, "Banners", 'Test Cases'!H:H, "Pass") -> 3 | C18: =COUNTIFS('Test Cases'!B:B, "Banners", 'Test Cases'!H:H, "Fail") -> 0 | D18: =COUNTIFS('Test Cases'!B:B, "Banners", 'Test Cases'!H:H, "Partial") -> 0 | E18: =COUNTIFS('Test Cases'!B:B, "Banners", 'Test Cases'!H:H, "<>Pass", 'Test Cases'!H:H, "<>Fail", 'Test Cases'!H:H, "<>Partial", 'Test Cases'!H:H, "<>") -> 0
A19: Right-click | B19: =COUNTIFS('Test Cases'!B:B, "Right-click", 'Test Cases'!H:H, "Pass") -> 10 | C19: =COUNTIFS('Test Cases'!B:B, "Right-click", 'Test Cases'!H:H, "Fail") -> 0 | D19: =COUNTIFS('Test Cases'!B:B, "Right-click", 'Test Cases'!H:H, "Partial") -> 0 | E19: =COUNTIFS('Test Cases'!B:B, "Right-click", 'Test Cases'!H:H, "<>Pass", 'Test Cases'!H:H, "<>Fail", 'Test Cases'!H:H, "<>Partial", 'Test Cases'!H:H, "<>") -> 0
A20: Generated Material | B20: =COUNTIFS('Test Cases'!B:B, "Generated Material", 'Test Cases'!H:H, "Pass") -> 3 | C20: =COUNTIFS('Test Cases'!B:B, "Generated Material", 'Test Cases'!H:H, "Fail") -> 1 | D20: =COUNTIFS('Test Cases'!B:B, "Generated Material", 'Test Cases'!H:H, "Partial") -> 1 | E20: =COUNTIFS('Test Cases'!B:B, "Generated Material", 'Test Cases'!H:H, "<>Pass", 'Test Cases'!H:H, "<>Fail", 'Test Cases'!H:H, "<>Partial", 'Test Cases'!H:H, "<>") -> 0
A21: Templates | B21: =COUNTIFS('Test Cases'!B:B, "Templates", 'Test Cases'!H:H, "Pass") -> 5 | C21: =COUNTIFS('Test Cases'!B:B, "Templates", 'Test Cases'!H:H, "Fail") -> 1 | D21: =COUNTIFS('Test Cases'!B:B, "Templates", 'Test Cases'!H:H, "Partial") -> 0 | E21: =COUNTIFS('Test Cases'!B:B, "Templates", 'Test Cases'!H:H, "<>Pass", 'Test Cases'!H:H, "<>Fail", 'Test Cases'!H:H, "<>Partial", 'Test Cases'!H:H, "<>") -> 1
A22: Rich-text insert | B22: =COUNTIFS('Test Cases'!B:B, "Rich-text insert", 'Test Cases'!H:H, "Pass") -> 5 | C22: =COUNTIFS('Test Cases'!B:B, "Rich-text insert", 'Test Cases'!H:H, "Fail") -> 0 | D22: =COUNTIFS('Test Cases'!B:B, "Rich-text insert", 'Test Cases'!H:H, "Partial") -> 0 | E22: =COUNTIFS('Test Cases'!B:B, "Rich-text insert", 'Test Cases'!H:H, "<>Pass", 'Test Cases'!H:H, "<>Fail", 'Test Cases'!H:H, "<>Partial", 'Test Cases'!H:H, "<>") -> 0
A23: Notes format | B23: =COUNTIFS('Test Cases'!B:B, "Notes format", 'Test Cases'!H:H, "Pass") -> 1 | C23: =COUNTIFS('Test Cases'!B:B, "Notes format", 'Test Cases'!H:H, "Fail") -> 0 | D23: =COUNTIFS('Test Cases'!B:B, "Notes format", 'Test Cases'!H:H, "Partial") -> 0 | E23: =COUNTIFS('Test Cases'!B:B, "Notes format", 'Test Cases'!H:H, "<>Pass", 'Test Cases'!H:H, "<>Fail", 'Test Cases'!H:H, "<>Partial", 'Test Cases'!H:H, "<>") -> 0
A24: Navigation | B24: =COUNTIFS('Test Cases'!B:B, "Navigation", 'Test Cases'!H:H, "Pass") -> 4 | C24: =COUNTIFS('Test Cases'!B:B, "Navigation", 'Test Cases'!H:H, "Fail") -> 0 | D24: =COUNTIFS('Test Cases'!B:B, "Navigation", 'Test Cases'!H:H, "Partial") -> 0 | E24: =COUNTIFS('Test Cases'!B:B, "Navigation", 'Test Cases'!H:H, "<>Pass", 'Test Cases'!H:H, "<>Fail", 'Test Cases'!H:H, "<>Partial", 'Test Cases'!H:H, "<>") -> 0
A25: Case alias | B25: =COUNTIFS('Test Cases'!B:B, "Case alias", 'Test Cases'!H:H, "Pass") -> 4 | C25: =COUNTIFS('Test Cases'!B:B, "Case alias", 'Test Cases'!H:H, "Fail") -> 0 | D25: =COUNTIFS('Test Cases'!B:B, "Case alias", 'Test Cases'!H:H, "Partial") -> 0 | E25: =COUNTIFS('Test Cases'!B:B, "Case alias", 'Test Cases'!H:H, "<>Pass", 'Test Cases'!H:H, "<>Fail", 'Test Cases'!H:H, "<>Partial", 'Test Cases'!H:H, "<>") -> 0
A26: Photo download | B26: =COUNTIFS('Test Cases'!B:B, "Photo download", 'Test Cases'!H:H, "Pass") -> 1 | C26: =COUNTIFS('Test Cases'!B:B, "Photo download", 'Test Cases'!H:H, "Fail") -> 0 | D26: =COUNTIFS('Test Cases'!B:B, "Photo download", 'Test Cases'!H:H, "Partial") -> 0 | E26: =COUNTIFS('Test Cases'!B:B, "Photo download", 'Test Cases'!H:H, "<>Pass", 'Test Cases'!H:H, "<>Fail", 'Test Cases'!H:H, "<>Partial", 'Test Cases'!H:H, "<>") -> 1
A27: Case report | B27: =COUNTIFS('Test Cases'!B:B, "Case report", 'Test Cases'!H:H, "Pass") -> 4 | C27: =COUNTIFS('Test Cases'!B:B, "Case report", 'Test Cases'!H:H, "Fail") -> 0 | D27: =COUNTIFS('Test Cases'!B:B, "Case report", 'Test Cases'!H:H, "Partial") -> 0 | E27: =COUNTIFS('Test Cases'!B:B, "Case report", 'Test Cases'!H:H, "<>Pass", 'Test Cases'!H:H, "<>Fail", 'Test Cases'!H:H, "<>Partial", 'Test Cases'!H:H, "<>") -> 0
A28: Manager | B28: =COUNTIFS('Test Cases'!B:B, "Manager", 'Test Cases'!H:H, "Pass") -> 6 | C28: =COUNTIFS('Test Cases'!B:B, "Manager", 'Test Cases'!H:H, "Fail") -> 0 | D28: =COUNTIFS('Test Cases'!B:B, "Manager", 'Test Cases'!H:H, "Partial") -> 0 | E28: =COUNTIFS('Test Cases'!B:B, "Manager", 'Test Cases'!H:H, "<>Pass", 'Test Cases'!H:H, "<>Fail", 'Test Cases'!H:H, "<>Partial", 'Test Cases'!H:H, "<>") -> 0
A29: Manager edit | B29: =COUNTIFS('Test Cases'!B:B, "Manager edit", 'Test Cases'!H:H, "Pass") -> 8 | C29: =COUNTIFS('Test Cases'!B:B, "Manager edit", 'Test Cases'!H:H, "Fail") -> 0 | D29: =COUNTIFS('Test Cases'!B:B, "Manager edit", 'Test Cases'!H:H, "Partial") -> 0 | E29: =COUNTIFS('Test Cases'!B:B, "Manager edit", 'Test Cases'!H:H, "<>Pass", 'Test Cases'!H:H, "<>Fail", 'Test Cases'!H:H, "<>Partial", 'Test Cases'!H:H, "<>") -> 0
A30: RTE editor | B30: =COUNTIFS('Test Cases'!B:B, "RTE editor", 'Test Cases'!H:H, "Pass") -> 11 | C30: =COUNTIFS('Test Cases'!B:B, "RTE editor", 'Test Cases'!H:H, "Fail") -> 1 | D30: =COUNTIFS('Test Cases'!B:B, "RTE editor", 'Test Cases'!H:H, "Partial") -> 0 | E30: =COUNTIFS('Test Cases'!B:B, "RTE editor", 'Test Cases'!H:H, "<>Pass", 'Test Cases'!H:H, "<>Fail", 'Test Cases'!H:H, "<>Partial", 'Test Cases'!H:H, "<>") -> 0
A31: Teams | B31: =COUNTIFS('Test Cases'!B:B, "Teams", 'Test Cases'!H:H, "Pass") -> 4 | C31: =COUNTIFS('Test Cases'!B:B, "Teams", 'Test Cases'!H:H, "Fail") -> 0 | D31: =COUNTIFS('Test Cases'!B:B, "Teams", 'Test Cases'!H:H, "Partial") -> 0 | E31: =COUNTIFS('Test Cases'!B:B, "Teams", 'Test Cases'!H:H, "<>Pass", 'Test Cases'!H:H, "<>Fail", 'Test Cases'!H:H, "<>Partial", 'Test Cases'!H:H, "<>") -> 0
A32: History | B32: =COUNTIFS('Test Cases'!B:B, "History", 'Test Cases'!H:H, "Pass") -> 2 | C32: =COUNTIFS('Test Cases'!B:B, "History", 'Test Cases'!H:H, "Fail") -> 0 | D32: =COUNTIFS('Test Cases'!B:B, "History", 'Test Cases'!H:H, "Partial") -> 0 | E32: =COUNTIFS('Test Cases'!B:B, "History", 'Test Cases'!H:H, "<>Pass", 'Test Cases'!H:H, "<>Fail", 'Test Cases'!H:H, "<>Partial", 'Test Cases'!H:H, "<>") -> 0
A33: Usage | B33: =COUNTIFS('Test Cases'!B:B, "Usage", 'Test Cases'!H:H, "Pass") -> 4 | C33: =COUNTIFS('Test Cases'!B:B, "Usage", 'Test Cases'!H:H, "Fail") -> 1 | D33: =COUNTIFS('Test Cases'!B:B, "Usage", 'Test Cases'!H:H, "Partial") -> 0 | E33: =COUNTIFS('Test Cases'!B:B, "Usage", 'Test Cases'!H:H, "<>Pass", 'Test Cases'!H:H, "<>Fail", 'Test Cases'!H:H, "<>Partial", 'Test Cases'!H:H, "<>") -> 0
A34: Read-only | B34: =COUNTIFS('Test Cases'!B:B, "Read-only", 'Test Cases'!H:H, "Pass") -> 2 | C34: =COUNTIFS('Test Cases'!B:B, "Read-only", 'Test Cases'!H:H, "Fail") -> 0 | D34: =COUNTIFS('Test Cases'!B:B, "Read-only", 'Test Cases'!H:H, "Partial") -> 0 | E34: =COUNTIFS('Test Cases'!B:B, "Read-only", 'Test Cases'!H:H, "<>Pass", 'Test Cases'!H:H, "<>Fail", 'Test Cases'!H:H, "<>Partial", 'Test Cases'!H:H, "<>") -> 0
A35: Dark mode | B35: =COUNTIFS('Test Cases'!B:B, "Dark mode", 'Test Cases'!H:H, "Pass") -> 1 | C35: =COUNTIFS('Test Cases'!B:B, "Dark mode", 'Test Cases'!H:H, "Fail") -> 0 | D35: =COUNTIFS('Test Cases'!B:B, "Dark mode", 'Test Cases'!H:H, "Partial") -> 0 | E35: =COUNTIFS('Test Cases'!B:B, "Dark mode", 'Test Cases'!H:H, "<>Pass", 'Test Cases'!H:H, "<>Fail", 'Test Cases'!H:H, "<>Partial", 'Test Cases'!H:H, "<>") -> 0
A36: Background | B36: =COUNTIFS('Test Cases'!B:B, "Background", 'Test Cases'!H:H, "Pass") -> 2 | C36: =COUNTIFS('Test Cases'!B:B, "Background", 'Test Cases'!H:H, "Fail") -> 0 | D36: =COUNTIFS('Test Cases'!B:B, "Background", 'Test Cases'!H:H, "Partial") -> 0 | E36: =COUNTIFS('Test Cases'!B:B, "Background", 'Test Cases'!H:H, "<>Pass", 'Test Cases'!H:H, "<>Fail", 'Test Cases'!H:H, "<>Partial", 'Test Cases'!H:H, "<>") -> 0
A37: Diagnostics | B37: =COUNTIFS('Test Cases'!B:B, "Diagnostics", 'Test Cases'!H:H, "Pass") -> 2 | C37: =COUNTIFS('Test Cases'!B:B, "Diagnostics", 'Test Cases'!H:H, "Fail") -> 0 | D37: =COUNTIFS('Test Cases'!B:B, "Diagnostics", 'Test Cases'!H:H, "Partial") -> 0 | E37: =COUNTIFS('Test Cases'!B:B, "Diagnostics", 'Test Cases'!H:H, "<>Pass", 'Test Cases'!H:H, "<>Fail", 'Test Cases'!H:H, "<>Partial", 'Test Cases'!H:H, "<>") -> 0
A38: Security | B38: =COUNTIFS('Test Cases'!B:B, "Security", 'Test Cases'!H:H, "Pass") -> 6 | C38: =COUNTIFS('Test Cases'!B:B, "Security", 'Test Cases'!H:H, "Fail") -> 0 | D38: =COUNTIFS('Test Cases'!B:B, "Security", 'Test Cases'!H:H, "Partial") -> 0 | E38: =COUNTIFS('Test Cases'!B:B, "Security", 'Test Cases'!H:H, "<>Pass", 'Test Cases'!H:H, "<>Fail", 'Test Cases'!H:H, "<>Partial", 'Test Cases'!H:H, "<>") -> 0
A39: Acknowledgements | B39: =COUNTIFS('Test Cases'!B:B, "Acknowledgements", 'Test Cases'!H:H, "Pass") -> 6 | C39: =COUNTIFS('Test Cases'!B:B, "Acknowledgements", 'Test Cases'!H:H, "Fail") -> 0 | D39: =COUNTIFS('Test Cases'!B:B, "Acknowledgements", 'Test Cases'!H:H, "Partial") -> 0 | E39: =COUNTIFS('Test Cases'!B:B, "Acknowledgements", 'Test Cases'!H:H, "<>Pass", 'Test Cases'!H:H, "<>Fail", 'Test Cases'!H:H, "<>Partial", 'Test Cases'!H:H, "<>") -> 0
A40: Suggestions | B40: =COUNTIFS('Test Cases'!B:B, "Suggestions", 'Test Cases'!H:H, "Pass") -> 5 | C40: =COUNTIFS('Test Cases'!B:B, "Suggestions", 'Test Cases'!H:H, "Fail") -> 0 | D40: =COUNTIFS('Test Cases'!B:B, "Suggestions", 'Test Cases'!H:H, "Partial") -> 0 | E40: =COUNTIFS('Test Cases'!B:B, "Suggestions", 'Test Cases'!H:H, "<>Pass", 'Test Cases'!H:H, "<>Fail", 'Test Cases'!H:H, "<>Partial", 'Test Cases'!H:H, "<>") -> 1
A41: UX | B41: =COUNTIFS('Test Cases'!B:B, "UX", 'Test Cases'!H:H, "Pass") -> 5 | C41: =COUNTIFS('Test Cases'!B:B, "UX", 'Test Cases'!H:H, "Fail") -> 0 | D41: =COUNTIFS('Test Cases'!B:B, "UX", 'Test Cases'!H:H, "Partial") -> 0 | E41: =COUNTIFS('Test Cases'!B:B, "UX", 'Test Cases'!H:H, "<>Pass", 'Test Cases'!H:H, "<>Fail", 'Test Cases'!H:H, "<>Partial", 'Test Cases'!H:H, "<>") -> 0

Sheet Diagnostics
A1: Diagnostics quick reference
A2: Capture a diagnostic log (easy) | B2: Popup → Diagnostics → switch ON 'Capture diagnostic log'. Refresh the Salesforce tab, reproduce the issue / run the tests, then Popup → 'Download log' to save a .txt to send to support. (The spreadsheet is your Pass/Fail record; this log is just technical detail for diagnosing failures.)
A3: Manual toggle (advanced) | B3: Service-worker console: chrome.storage.local.set({ cyforDebug: true }); then refresh the Salesforce tab. Disable with false.
A4: Open the service-worker console | B4: chrome://extensions → CYFOR Nucleus Enhancer → 'Inspect views: service worker'.
A5: Content-script logs | B5: Appear in the PAGE console (F12 on the Salesforce tab). Filter with [Cyfor.
A6: Inspect stored state | B6: chrome.storage.local.get(null, console.log) · sfOAuthUser · sfRemoteTemplates / sfTemplatesSyncedAt · usageLogError
A7: Force a sync | B7: chrome.runtime.sendMessage({action:'sfTemplates.sync', forceRefresh:true}, console.log)
A8: Check multi-team / limits | B8: chrome.runtime.sendMessage({action:'sfTemplates.listAll'}, r=>console.log(r.fields)) → fields.teamsMulti, fields.contentMaxLength
A9: Insertion path | B9: [Cyfor:insert] method = paste (good) vs insertHTML/innerHTML (fallback) — if rich content is lost, capture this.
A10: Right-click native menu | B10: Set browser zoom to 100% (zoom shifts elementFromPoint).
A11: Full cheat-sheet | B11: docs/Nucleus_Enhancer_Diagnostics.md
